Workbook

Sheet Report
A1: Academic Portal - Test Coverage & Feature Report
A2: Summary of test cases per module, calculated via Excel formulas
A4: Total Modules | B4: Total Test Cases | C4: High Priority TCs | D4: Medium Priority TCs | E4: Low Priority TCs
A5: =COUNTA(A9:A17) | B5: =E18 | C5: =B18 | D5: =C18 | E5: =D18
A7: Module Test Case Breakdown by Priority
A8: Module Name | B8: High Priority | C8: Medium Priority | D8: Low Priority | E8: Total TCs
A9: Module 01 | B9: =COUNTIF('Module 01'!$N$2:$N$500, "High") | C9: =COUNTIF('Module 01'!$N$2:$N$500, "Medium") | D9: =COUNTIF('Module 01'!$N$2:$N$500, "Low") | E9: =SUM(B9:D9)
A10: Module 02 | B10: =COUNTIF('Module 02'!$N$2:$N$500, "High") | C10: =COUNTIF('Module 02'!$N$2:$N$500, "Medium") | D10: =COUNTIF('Module 02'!$N$2:$N$500, "Low") | E10: =SUM(B10:D10)
A11: Module 03 | B11: =COUNTIF('Module 03'!$N$2:$N$500, "High") | C11: =COUNTIF('Module 03'!$N$2:$N$500, "Medium") | D11: =COUNTIF('Module 03'!$N$2:$N$500, "Low") | E11: =SUM(B11:D11)
A12: Module 04 | B12: =COUNTIF('Module 04'!$N$2:$N$500, "High") | C12: =COUNTIF('Module 04'!$N$2:$N$500, "Medium") | D12: =COUNTIF('Module 04'!$N$2:$N$500, "Low") | E12: =SUM(B12:D12)
A13: Module 05 | B13: =COUNTIF('Module 05'!$N$2:$N$500, "High") | C13: =COUNTIF('Module 05'!$N$2:$N$500, "Medium") | D13: =COUNTIF('Module 05'!$N$2:$N$500, "Low") | E13: =SUM(B13:D13)
A14: Module 06 | B14: =COUNTIF('Module 06'!$O$2:$O$500, "High") | C14: =COUNTIF('Module 06'!$O$2:$O$500, "Medium") | D14: =COUNTIF('Module 06'!$O$2:$O$500, "Low") | E14: =SUM(B14:D14)
A15: Module 07 | B15: =COUNTIF('Module 07'!$N$2:$N$500, "High") | C15: =COUNTIF('Module 07'!$N$2:$N$500, "Medium") | D15: =COUNTIF('Module 07'!$N$2:$N$500, "Low") | E15: =SUM(B15:D15)
A16: Module 08 | B16: =COUNTIF('Module 08'!$N$2:$N$500, "High") | C16: =COUNTIF('Module 08'!$N$2:$N$500, "Medium") | D16: =COUNTIF('Module 08'!$N$2:$N$500, "Low") | E16: =SUM(B16:D16)
A17: Module 09 | B17: =COUNTIF('Module 09'!$N$2:$N$500, "High") | C17: =COUNTIF('Module 09'!$N$2:$N$500, "Medium") | D17: =COUNTIF('Module 09'!$N$2:$N$500, "Low") | E17: =SUM(B17:D17)
A18: Total | B18: =SUM(B9:B17) | C18: =SUM(C9:C17) | D18: =SUM(D9:D17) | E18: =SUM(E9:E17)

Sheet Summary
A1: Academic Portal - Comprehensive Test Suite & Feature Breakdown
A3: Total Modules | B3: Total Features | C3: Total Test Cases | D3: High Priority | E3: Medium Priority
A4: 9 | B4: 81 | C4: 251 | D4: 192 | E4: 55
A6: 1. Module Summary Overview
A7: Module Name | B7: Total Test Cases | C7: High Priority | D7: Medium Priority | E7: Low Priority
A8: Module 01 | B8: 33 | C8: 27 | D8: 6 | E8: 0
A9: Module 02 | B9: 25 | C9: 17 | D9: 8 | E9: 0
A10: Module 03 | B10: 22 | C10: 19 | D10: 2 | E10: 0
A11: Module 04 | B11: 33 | C11: 19 | D11: 12 | E11: 2
A12: Module 05 | B12: 23 | C12: 19 | D12: 4 | E12: 0
A13: Module 06 | B13: 31 | C13: 28 | D13: 3 | E13: 0
A14: Module 07 | B14: 41 | C14: 32 | D14: 9 | E14: 0
A15: Module 08 | B15: 20 | C15: 12 | D15: 7 | E15: 1
A16: Module 09 | B16: 23 | C16: 19 | D16: 4 | E16: 0
A17: Total | B17: 251 | C17: 192 | D17: 55 | E17: 3
A20: 2. Feature Categorization Breakdown
A21: Module | B21: Feature ID | C21: Feature Name | D21: Test Cases | E21: High Priority | F21: Medium Priority | G21: Low Priority
A22: Module 01 | B22: M01-F01 | C22: Batch Creation | D22: 7 | E22: 7 | F22: 0 | G22: 0
A23: Module 01 | B23: M01-F02 | C23: Batch Editing | D23: 3 | E23: 3 | F23: 0 | G23: 0
A24: Module 01 | B24: M01-F03 | C24: Batch Archiving | D24: 3 | E24: 2 | F24: 1 | G24: 0
A25: Module 01 | B25: M01-F04 | C25: Single Student Creation | D25: 3 | E25: 3 | F25: 0 | G25: 0
A26: Module 01 | B26: M01-F05 | C26: Bulk Student Import | D26: 4 | E26: 4 | F26: 0 | G26: 0
A27: Module 01 | B27: M01-F06 | C27: Student Editing | D27: 2 | E27: 2 | F27: 0 | G27: 0
A28: Module 01 | B28: M01-F07 | C28: Follow-up Flag | D28: 1 | E28: 1 | F28: 0 | G28: 0
A29: Module 01 | B29: M01-F08 | C29: Student Status Management | D29: 2 | E29: 2 | F29: 0 | G29: 0
A30: Module 01 | B30: M01-F09 | C30: Search & Filter | D30: 3 | E30: 0 | F30: 3 | G30: 0
A31: Module 01 | B31: M01-F10 | C31: Dashboard Overview | D31: 2 | E31: 0 | F31: 2 | G31: 0
A32: Module 01 | B32: M01-SEC | C32: Access Control & Security | D32: 3 | E32: 3 | F32: 0 | G32: 0
A33: Module 02 | B33: M02-F01 | C33: Single Observation Entry | D33: 3 | E33: 3 | F33: 0 | G33: 0
... A102: Module 09 | B102: M09-F10 | C102: Responsive Design | D102: 1 | E102: 0 | F102: 1 | G102: 0

Sheet Module 01
A1: ID | B1: Module | C1: Feature ID | D1: Feature Name | E1: Title | F1: Objective | G1: Preconditions | H1: TestData | I1: Steps | J1: ExpectedResult | K1: Actual Result | L1: Status | M1: Evidence | N1: Priority | O1: Notes
A2: TC-M01-001 | B2: Module 01 | C2: M01-F01 | D2: Batch Creation | E2: Create Batch with Valid Name | F2: Verify that a batch can be created using a valid batch name matching the format PNVyyX (e.g. PNV26A). | G2: Staff user is logged in. | H2: BatchName=PNV26A; Status=Active | I2: 1. Open Batch Management; 2. Click Create Batch; 3. Enter PNV26A as Batch Name; 4. Select Active status; 5. Click Save | J2: Batch is created successfully. Success notification appears. PNV26A is displayed in the batch list. | K2: Batch is created successfully. Success notification appears. PNV26A is displayed in the batch list. | L2: Passed | N2: High | O2: Related Requirement: M01-F01, Scenario: BS-01
A3: TC-M01-002 | B3: Module 01 | C3: M01-F01 | D3: Batch Creation | E3: Create Batch with Invalid Name Format - Lowercase Letter | F3: Verify that the system rejects batch creation if the alphabet code is in lowercase (e.g. PNV26a). | G3: Staff user is logged in. | H3: BatchName=PNV26a; Status=Active | I3: 1. Open Batch Management; 2. Click Create Batch; 3. Enter PNV26a as Batch Name; 4. Click Save | J3: System rejects creation. Error message appears: "Invalid batch name. Use format PNVyyX (e.g., PNV26A)." | K3: System rejects creation. Error message appears: "Invalid batch name. Use format PNVyyX (e.g., PNV26A)." | L3: Passed | N3: High | O3: Related Requirement: M01-F01, Scenario: BS-01
A4: TC-M01-003 | B4: Module 01 | C4: M01-F01 | D4: Batch Creation | E4: Create Batch with Invalid Name Format - Wrong Prefix | F4: Verify that the system rejects batch creation if the prefix is not PNV (e.g. ABC26A). | G4: Staff user is logged in. | H4: BatchName=ABC26A; Status=Active | I4: 1. Open Batch Management; 2. Click Create Batch; 3. Enter ABC26A as Batch Name; 4. Click Save | J4: System rejects creation. Error message appears: "Invalid batch name. Use format PNVyyX (e.g., PNV26A)." | K4: System rejects creation. Error message appears: "Invalid batch name. Use format PNVyyX (e.g., PNV26A)." | L4: Passed | N4: High | O4: Related Requirement: M01-F01, Scenario: BS-01
A5: TC-M01-004 | B5: Module 01 | C5: M01-F01 | D5: Batch Creation | E5: Create Batch with Invalid Name Format - 4-digit Year | F5: Verify that the system rejects batch creation if the year is written in 4 digits (e.g. PNV2026A). | G5: Staff user is logged in. | H5: BatchName=PNV2026A; Status=Active | I5: 1. Open Batch Management; 2. Click Create Batch; 3. Enter PNV2026A as Batch Name; 4. Click Save | J5: System rejects creation. Error message appears: "Invalid batch name. Use format PNVyyX (e.g., PNV26A)." | K5: System rejects creation. Error message appears: "Invalid batch name. Use format PNVyyX (e.g., PNV26A)." | L5: Passed | N5: High | O5: Related Requirement: M01-F01, Scenario: BS-01
A6: TC-M01-005 | B6: Module 01 | C6: M01-F01 | D6: Batch Creation | E6: Create Batch with Invalid Name Format - Multiple Letters | F6: Verify that the system rejects batch creation if there are multiple suffix letters (e.g. PNV26AA). | G6: Staff user is logged in. | H6: BatchName=PNV26AA; Status=Active | I6: 1. Open Batch Management; 2. Click Create Batch; 3. Enter PNV26AA as Batch Name; 4. Click Save | J6: System rejects creation. Error message appears: "Invalid batch name. Use format PNVyyX (e.g., PNV26A)." | K6: System rejects creation. Error message appears: "Invalid batch name. Use format PNVyyX (e.g., PNV26A)." | L6: Passed | N6: High | O6: Related Requirement: M01-F01, Scenario: BS-01
A7: TC-M01-006 | B7: Module 01 | C7: M01-F01 | D7: Batch Creation | E7: Create Batch with Empty Name | F7: Verify that a batch cannot be saved with an empty name. | G7: Staff user is logged in. | H7: BatchName=; Status=Active | I7: 1. Open Batch Management; 2. Click Create Batch; 3. Leave Batch Name empty; 4. Click Save | J7: System rejects save. Error message appears indicating batch name is required. Saving is blocked. | K7: System rejects save. Error message appears indicating batch name is required. Saving is blocked. | L7: Passed | N7: High | O7: Related Requirement: M01-F01, Scenario: BS-01
A8: TC-M01-007 | B8: Module 01 | C8: M01-F01 | D8: Batch Creation | E8: Create Batch with Duplicate Name | F8: Verify that the system rejects batch creation if the name already exists (case-insensitive). | G8: Staff user is logged in. Batch PNV26A already exists. | H8: BatchName=pnv26a; Status=Active | I8: 1. Open Batch Management; 2. Click Create Batch; 3. Enter pnv26a (lowercase) as Batch Name; 4. Click Save | J8: System rejects creation. Error message appears: "A batch named "PNV26A" already exists." | K8: System rejects creation. Error message appears: "A batch named "PNV26A" already exists." | L8: Passed | N8: High | O8: Related Requirement: M01-F01, Scenario: BS-01
A9: TC-M01-008 | B9: Module 01 | C9: M01-F02 | D9: Batch Editing | E9: Rename Batch with Valid Unique Name | F9: Verify that an existing batch can be successfully renamed to a new valid unique name. | G9: Staff user is logged in. Batch PNV26A exists. | H9: OldBatchName=PNV26A; NewBatchName=PNV26C | I9: 1. Open Batch Management; 2. Select batch PNV26A and click Edit; 3. Change name to PNV26C; 4. Click Save | J9: Batch is renamed successfully. Success notification appears. PNV26C is displayed in the batch list. | K9: Batch is renamed successfully. Success notification appears. PNV26C is displayed in the batch list. | L9: Passed | N9: High | O9: Related Requirement: M01-F02, Scenario: BS-02
A10: TC-M01-009 | B10: Module 01 | C10: M01-F02 | D10: Batch Editing | E10: Rename Batch to Existing Name Blocked | F10: Verify that renaming a batch to a name that already exists is blocked by the system. | G10: Staff user is logged in. Batches PNV26A and PNV26B exist. | H10: TargetBatch=PNV26B; NewBatchName=PNV26A | I10: 1. Open Batch Management; 2. Select batch PNV26B and click Edit; 3. Change name to PNV26A; 4. Click Save | J10: System rejects update. Error message appears: "A batch named "PNV26A" already exists." | K10: System rejects update. Error message appears: "A batch named "PNV26A" already exists." | L10: Passed | N10: High | O10: Related Requirement: M01-F02, Scenario: BS-02
A11: TC-M01-010 | B11: Module 01 | C11: M01-F02 | D11: Batch Editing | E11: Rename Batch to Invalid Format Blocked | F11: Verify that renaming a batch to an invalid format is blocked by the system. | G11: Staff user is logged in. Batch PNV26A exists. | H11: TargetBatch=PNV26A; NewBatchName=PNV26AA | I11: 1. Open Batch Management; 2. Select batch PNV26A and click Edit; 3. Change name to PNV26AA; 4. Click Save | J11: System rejects update. Error message appears: "Invalid batch name. Use format PNVyyX (e.g., PNV26A)." | K11: System rejects update. Error message appears: "Invalid batch name. Use format PNVyyX (e.g., PNV26A)." | L11: Passed | N11: High | O11: Related Requirement: M01-F02, Scenario: BS-02
A12: TC-M01-011 | B12: Module 01 | C12: M01-F03 | D12: Batch Archiving | E12: Archive Active Batch | F12: Verify that an active batch can be archived by setting its Active status to false. | G12: Staff user is logged in. Batch PNV26A is active. | H12: BatchName=PNV26A; ActiveStatus=false | I12: 1. Open Batch Management; 2. Select batch PNV26A and click Archive (or edit and uncheck Active); 3. Confirm archive action | J12: Batch is archived successfully. Active status becomes false in database. The batch is hidden from active lists. | K12: Batch is archived successfully. Active status becomes false in database. The batch is hidden from active lists. | L12: Passed | N12: High | O12: Related Requirement: M01-F03, Scenario: BS-03
A13: TC-M01-012 | B13: Module 01 | C13: M01-F03 | D13: Batch Archiving | E13: Reactivate Archived Batch | F13: Verify that an archived batch can be reactivated by setting its Active status to true. | G13: Staff user is logged in. Batch PNV26A is archived (Active = false). | H13: BatchName=PNV26A; ActiveStatus=true | I13: 1. Open Batch Management; 2. Filter by Archived batches; 3. Select batch PNV26A and click Reactivate; 4. Confirm reactivate action | J13: Batch is reactivated successfully. Active status becomes true in database. The batch appears in active lists. | K13: Batch is reactivated successfully. Active status becomes true in database. The batch appears in active lists. | L13: Passed | N13: High | O13: Related Requirement: M01-F03, Scenario: BS-03
... A34: TC-M01-033 | B34: Module 01 | C34: M01-F06 | D34: Student Editing | E34: Edit Student Email to Invalid Format Blocked | F34: Verify that editing a student's email to an invalid format is blocked. | G34: Staff user is logged in. Student ST001 exists. | H34: StudentCode=ST001; NewEmail=nguyenvana_invalid_email | I34: 1. Open student list; 2. Select ST001 and click Edit; 3. Change email to 'nguyenvana_invalid_email'; 4. Click Save | J34: The system blocks saving and displays a validation error message requiring a valid email format. The email field is highlighted in red. | K34: The system successfully updated the email address, even though the format was incorrect. | L34: Failed | N34: High | O34: Related Requirement: M01-F06, Validation Rules

Sheet Module 02
A1: ID | B1: Module | C1: Feature ID | D1: Feature Name | E1: Title | F1: Objective | G1: Preconditions | H1: TestData | I1: Steps | J1: ExpectedResult | K1: Actual Result | L1: Status | M1: Evidence | N1: Priority | O1: Notes
A2: TC-M02-001 | B2: Module 02 | C2: M02-F01 | D2: Single Observation Entry | E2: Record Single Student Observation with Valid Ratings | F2: Verify that staff can record observations for a single student across all four subjects with valid ratings (G, S, NI). | G2: Staff user is logged in. Batch PNV26A and student ST001 exist. | H2: Student=ST001; Date=2026-07-17; IT_Rating=G; IT_Notes=Excellent coding skills; PLT_Rating=S; PLT_Notes=Active participation; English_Rating=NI; English_Notes=Needs vocabulary practice; DA_Rating=S; DA_Notes=Good design sense | I2: 1. Open Scan Management; 2. Select Batch PNV26A and Student ST001; 3. Select Observation Date: 17/07/2026; 4. For IT, select rating G and enter notes 'Excellent coding skills'; 5. For PLT, select rating S and enter notes 'Active participation'; 6. For English, select rating NI and enter notes 'Needs vocabulary practice'; 7. For DA, select rating S and enter notes 'Good design sense'; 8. Click Save | J2: Observation is saved successfully. A success message appears. The student's record is displayed in the list with correct ratings and notes. | K2: Observation is saved successfully. A success message appears. The student's record is displayed in the list with correct ratings and notes. | L2: Passed | N2: High | O2: Related Requirement: M02-F01, Scenario: SC-01
A3: TC-M02-002 | B3: Module 02 | C3: M02-F01 | D3: Single Observation Entry | E3: Record Single Student Observation with Empty Ratings | F3: Verify that staff can record observations with ratings set to '-' (Not Yet Assessed) and notes empty. | G3: Staff user is logged in. Batch PNV26A and student ST001 exist. | H3: Student=ST001; Date=2026-07-17; Ratings='-'; Notes='' | I3: 1. Open Scan Management; 2. Select Batch PNV26A and Student ST001; 3. Select Observation Date: 17/07/2026; 4. Leave all subject ratings as '-' and notes empty; 5. Click Save | J3: Observation is saved successfully. The ratings are stored as empty/unassessed in the database. No validation error occurs. | K3: Observation is saved successfully. The ratings are stored as empty/unassessed in the database. No validation error occurs. | L3: Passed | N3: High | O3: Related Requirement: M02-F01, Scenario: SC-01
A4: TC-M02-003 | B4: Module 02 | C4: M02-F02 | D4: Auto Rating Suggestion | E4: Auto Rating Suggestion Triggered After Typing Notes | F4: Verify that the system suggests a performance rating (G, S, or NI) approximately 400ms after user stops typing notes. | G4: Staff user is logged in. | H4: Subject=IT; Notes='The student solved all problems quickly and helped other classmates.' | I4: 1. Open observation entry for IT; 2. Start typing the notes: 'The student solved all problems quickly and helped other classmates.'; 3. Stop typing and wait for 400 milliseconds; 4. Observe the rating selector | J4: An auto-rating suggestion (G/excellent) is automatically selected or suggested adjacent to the rating field after 400ms of inactivity. | K4: An auto-rating suggestion (G/excellent) is automatically selected or suggested adjacent to the rating field after 400ms of inactivity. | L4: Passed | N4: High | O4: Related Requirement: M02-F02, Scenario: SC-02
A5: TC-M02-004 | B5: Module 02 | C5: M02-F02 | D5: Auto Rating Suggestion | E5: Overwrite Auto Rating Suggestion | F5: Verify that staff members can manually overwrite an auto-suggested rating. | G5: Staff user is logged in. System has suggested rating 'G' after notes were typed. | H5: Subject=IT; Notes='Good work but missed classes'; SuggestedRating=G; OverwrittenRating=S | I5: 1. Type notes that trigger a 'G' suggestion; 2. Wait for the suggestion to appear; 3. Click the rating dropdown and manually change the rating to 'S'; 4. Click Save | J5: The manually selected rating 'S' replaces the suggestion 'G'. The record is saved successfully with rating 'S'. | K5: The manually selected rating 'S' replaces the suggestion 'G'. The record is saved successfully with rating 'S'. | L5: Passed | N5: High | O5: Related Requirement: M02-F02, Scenario: SC-02
A6: TC-M02-005 | B6: Module 02 | C6: M02-F03 | D6: Batch Entry – All Subjects | E6: Batch Entry for All Subjects simultaneously | F6: Verify that staff can record observations for multiple students across all subjects simultaneously using spreadsheet-style entry. | G6: Staff user is logged in. Batch PNV26A contains multiple active students (ST001, ST002). | H6: Grid of ratings and notes for ST001 and ST002. | I6: 1. Open Scan Management and choose Batch Entry - All Subjects; 2. Select Batch PNV26A and Date: 17/07/2026; 3. On the grid, enter ratings and notes for ST001 (IT=G, PLT=S, English=S, DA=S) and ST002 (IT=S, PLT=NI, English=S, DA=S); 4. Click Save All | J6: System saves all observation data simultaneously. Success notification appears (e.g.: "Saved 2 students"). Data is displayed accurately in the list. | K6: System saves all observation data simultaneously. Success notification appears (e.g.: "Saved 2 students"). Data is displayed accurately in the list. | L6: Passed | N6: High | O6: Related Requirement: M02-F03, Scenario: SC-03
A7: TC-M02-006 | B7: Module 02 | C7: M02-F04 | D7: Batch Entry – By Subject | E7: Batch Entry by Subject | F7: Verify that teachers can enter observations for a single subject for multiple students in batch mode. | G7: Staff user is logged in. | H7: Subject=English; Ratings and notes for ST001, ST002, ST003. | I7: 1. Open Scan Management and choose Batch Entry - By Subject; 2. Select Batch PNV26A, Date: 17/07/2026, and Subject: English; 3. Fill ratings and notes for English for ST001, ST002, and ST003; 4. Click Save | J7: English observations are saved successfully for all selected students. Other subjects (IT, PLT, DA) for these students remain unaffected. | K7: English observations are saved successfully for all selected students. Other subjects (IT, PLT, DA) for these students remain unaffected. | L7: Passed | N7: High | O7: Related Requirement: M02-F04, Scenario: SC-04
A8: TC-M02-007 | B8: Module 02 | C8: M02-F05 | D8: Observation Editing | E8: Edit Existing Observation Ratings and Notes | F8: Verify that staff can edit the ratings and notes of an existing observation record (before the session is complete). | G8: Staff user is logged in. Student ST001 has an observation on 17/07/2026. | H8: Student=ST001; Date=2026-07-17; NewITRating=S; NewITNotes=Needs some improvements. | I8: 1. Open Scan Management; 2. Search for ST001 and click Edit on observation for 17/07/2026; 3. Change IT rating to 'S' and notes to 'Needs some improvements.'; 4. Click Save | J8: Observation is updated successfully. A success notification is displayed. The new rating 'S' and notes display correctly. | K8: Observation is updated successfully. A success notification is displayed. The new rating 'S' and notes display correctly. | L8: Passed | N8: High | O8: Related Requirement: M02-F05, Scenario: SC-05
A9: TC-M02-008 | B9: Module 02 | C9: M02-F05 | D9: Observation Editing | E9: Observation Date Locked and Cannot Be Changed | F9: Verify that the observation date of an existing record is locked and cannot be edited. | G9: Staff user is logged in. Student ST001 has an observation on 17/07/2026. | H9: Student=ST001; Date=2026-07-17 | I9: 1. Open Scan Management; 2. Select ST001 observation on 17/07/2026 and click Edit; 3. Check the Observation Date field; 4. Attempt to modify the date | J9: The Observation Date field is disabled (read-only) and cannot be interacted with or modified. | K9: The evaluation date is subject to change at will without notice. | L9: Failed | N9: High | O9: Related Requirement: M02-F05, Scenario: SC-05, Business Rules
A10: TC-M02-009 | B10: Module 02 | C10: M02-F06 | D10: Duplicate Detection & Merge | E10: Duplicate Observation Merged - Less Than 3 Subjects Completed | F10: Verify that a duplicate student/date observation is merged into the existing record if less than 3 subjects are completed in the existing record. | G10: Staff user is logged in. Student ST001 has an observation on 17/07/2026 with only IT and PLT completed. | H10: Student=ST001; Date=2026-07-17; English_Rating=S; English_Notes=Good English vocabulary; DA_Rating=S | I10: 1. Submit a new observation for ST001 on 17/07/2026 with English rating 'S', notes 'Good English vocabulary', and DA rating 'S'; 2. Click Save | J10: Save is accepted. English and DA ratings are merged into the existing ST001 row. Message displays: "Added to existing session.". | K10: The system does not merge duplicate reviews. | L10: Failed | N10: High | O10: Related Requirement: M02-F06, Scenario: SC-06, Rule 1
A11: TC-M02-010 | B11: Module 02 | C11: M02-F06 | D11: Duplicate Detection & Merge | E11: Duplicate Observation Rejected - 3 or More Subjects Completed | F11: Verify that a duplicate student/date observation is rejected if 3 or more subjects are already completed in the existing record. | G11: Staff user is logged in. Student ST001 has an observation on 17/07/2026 with IT, PLT, and English completed. | H11: Student=ST001; Date=2026-07-17; DA_Rating=G; DA_Notes=Excellent design work | I11: 1. Attempt to save a new observation for ST001 on 17/07/2026 containing DA rating 'G'; 2. Click Save | J11: Save is rejected. Error message displays: "A feedback record for this date already exists.". New record is not saved. | K11: New ratings are saved and no error messages are displayed even if the student has previously given a rating. | L11: Failed | N11: High | O11: Related Requirement: M02-F06, Scenario: SC-07, Rule 2
A12: TC-M02-011 | B12: Module 02 | C12: M02-F07 | D12: Session Management | E12: Mark Session Complete - Auto-fill N/A for Unassessed Students | F12: Verify that marking a session complete automatically fills ratings for unassessed students with N/A and closes the session. | G12: Staff user is logged in. Batch PNV26A session on 17/07/2026 is complete for ST001 but ST002 has no observations. | H12: Batch=PNV26A; Date=2026-07-17 | I12: 1. Open progress dashboard for PNV26A on 17/07/2026; 2. Click Mark Session Complete; 3. Check session status and ST002 record | J12: Session status becomes 'Complete'. Student ST002 is automatically filled with 'N/A' for all subjects. No unassessed students remain. | K12: Session status becomes 'Complete'. Student ST002 is automatically filled with 'N/A' for all subjects. No unassessed students remain. | L12: Passed | N12: High | O12: Related Requirement: M02-F07, Scenario: SC-08
A13: TC-M02-012 | B13: Module 02 | C13: M02-F07 | D13: Session Management | E13: Block Edits on Completed Session | F13: Verify that staff cannot edit or create observations once a session is marked Complete. | G13: Staff user is logged in. Batch PNV26A session on 17/07/2026 is marked Complete. | H13: Batch=PNV26A; Date=2026-07-17 | I13: 1. Open completed session for PNV26A on 17/07/2026; 2. Try clicking Edit or Add Observation for this date; 3. Observe UI and server response if save is sent | J13: Edit/Add buttons are hidden or disabled. Server rejects any manual save attempts with error "Form may be outdated." or "Session outdated.". | K13: The edit button is disabled, making it impossible to edit student evaluation information. | L13: Passed | N13: High | O13: Related Requirement: M02-F07, Scenario: SC-08, Business Rules
... A26: TC-M02-025 | B26: Module 02 | C26: M02-F07 | D26: Session Management | E26: Block Editing of Auto-filled N/A Observations | F26: Verify that once a session is completed, the auto-filled N/A observations are locked and cannot be edited. | G26: Staff user is logged in. Batch PNV26A session on 17/07/2026 has been completed. Student ST002 was auto-filled with N/A. | H26: Student=ST002; Date=2026-07-17 | I26: 1. Open observation list for PNV26A on 17/07/2026; 2. Select ST002 (showing N/A for all subjects); 3. Search for Edit button or click fields to modify rating/notes; 4. Attempt to save modifications | J26: Rating select boxes and comments are read-only. Edit controls are hidden or disabled. No changes can be saved. | K26: Rating select boxes and comments are read-only. Edit controls are hidden or disabled. No changes can be saved. | L26: Passed | N26: High | O26: Related Requirement: M02-F07, Scenario: SC-08, Session Completion

Sheet Module 03
A1: ID | B1: Module | C1: Feature ID | D1: Feature Name | E1: Title | F1: Objective | G1: Preconditions | H1: TestData | I1: Steps | J1: ExpectedResult | K1: Actual Result | L1: Status | M1: Evidence | N1: Priority | O1: Notes
A2: TC-M03-001 | B2: Module 03 | C2: M03-F01 | D2: Course / Subject Creation | E2: Create New Subject Manually | F2: Verify that staff can create a new subject manually by choosing a batch and semester. | G2: Staff user is logged in. Batch PNV26A and Semester 1 exist. | H2: SubjectName=Programming; Batch=PNV26A; Semester=Semester 1 | I2: 1. Navigate to Academic Management; 2. Click Create Subject; 3. Enter subject name 'Programming'; 4. Select Batch 'PNV26A' and Semester 'Semester 1'; 5. Click Save | J2: Subject is created successfully. Success notification appears. 'Programming' belongs to PNV26A, Semester 1 in subject list. | L2: Passed | N2: High | O2: Related Requirement: M03-F01
A3: TC-M03-002 | B3: Module 03 | C3: M03-F01 | D3: Course / Subject Creation | E3: Bulk Subject Creation via Valid CSV | F3: Verify that staff can create multiple subjects simultaneously by importing a valid CSV file. | G3: Staff user is logged in. Batch PNV26A and Semester 1 exist. | H3: CSV containing: SubjectName, Batch, Semester columns with 'Programming,PNV26A,Semester 1' and 'English,PNV26A,Semester 1' | I3: 1. Navigate to Academic Management; 2. Click Import Subjects via CSV; 3. Select valid CSV file; 4. Click Import | J3: Subjects are imported successfully. Message displays 'Imported 2 subjects'. Programming and English appear in subject list. | L3: Passed | N3: High | O3: Related Requirement: M03-F01
A4: TC-M03-003 | B4: Module 03 | C4: M03-F01 | D4: Course / Subject Creation | E4: Create Subject Fails due to Empty Subject Name | F4: Verify that the system blocks subject creation and warns if the subject name is empty. | G4: Staff user is logged in. | H4: SubjectName=Empty; Batch=PNV26A; Semester=Semester 1 | I4: 1. Navigate to Academic Management; 2. Click Create Subject; 3. Leave Subject Name blank; 4. Select Batch PNV26A and Semester 1; 5. Click Save | J4: Saving is blocked. Error message 'Subject Name is required' displays. Name field is highlighted in red. | K4: Hệ thống không thực hiện việc tạo môn học nhưng cũng không có thông báo nào cho người dùng. | L4: Failed | N4: High | O4: Related Requirement: M03-F01, Validation Rules
A5: TC-M03-004 | B5: Module 03 | C5: M03-F02 | D5: Grade Entry Structure | E5: Single Student Grade Entry | F5: Verify that staff can input periodic and regular test grades for a specific student in a subject. | G5: Programming subject of batch PNV26A exists. Student ST001 belongs to batch PNV26A. | H5: StudentID=ST001; Subject=Programming; KT_TX=7.5; DK1=8.0 | I5: 1. Open Academic Management and select subject 'Programming'; 2. Find student ST001 in grade list; 3. Click KT TX cell and enter '7.5'; 4. Click DK1 cell and enter '8.0'; 5. Click Save | J5: Grades are saved successfully. Success message displays. '7.5' and '8.0' appear on ST001's grade row. | L5: Not Run | N5: High | O5: Related Requirement: M03-F02
A6: TC-M03-005 | B6: Module 03 | C6: M03-F03 | D6: Automatic TBKT Calculation | E6: Auto TBKT Calculation and Exam Eligibility (TBKT >= 5.0) | F6: Verify that the system automatically calculates average grade (TBKT) based on weighted formula and grants exam eligibility (Eligible = YES) if TBKT >= 5.0. | G6: Programming subject has 1 periodic test weight. Student ST001 has grades. | H6: KT_TX=7.0; DK1=8.0 | I6: 1. Select subject 'Programming'; 2. Input KT_TX=7.0 and DK1=8.0 for ST001; 3. Click Save; 4. Observe TBKT column and Eligible status for ST001 | J6: TBKT is calculated as 7.67 (formula: (7.0*1 + 8.0*2)/3 = 7.67). Exam eligibility displays 'YES'. | L6: Not Run | N6: High | O6: Related Requirement: M03-F03
A7: TC-M03-006 | B7: Module 03 | C7: M03-F03 | D7: Automatic TBKT Calculation | E7: Auto TBKT Calculation and Exam Ineligibility (TBKT < 5.0) | F7: Verify that the system automatically calculates TBKT and blocks exam eligibility (Eligible = NO) if TBKT < 5.0. | G7: Programming subject has 1 periodic test weight. Student ST002 has grades. | H7: KT_TX=3.0; DK1=5.0 | I7: 1. Select subject 'Programming'; 2. Input KT_TX=3.0 and DK1=5.0 for ST002; 3. Click Save; 4. Observe TBKT column and Eligible status for ST002 | J7: TBKT is calculated as 4.33 (formula: (3.0*1 + 5.0*2)/3 = 4.33). Exam eligibility displays 'NO'. | L7: Not Run | N7: High | O7: Related Requirement: M03-F03
A8: TC-M03-007 | B8: Module 03 | C8: M03-F03 | D8: Automatic TBKT Calculation | E8: Block Final Exam Grade Entry When Ineligible (TBKT < 5.0) | F8: Verify that final exam grade input is disabled and blocked for students with status Eligible = NO. | G8: Student ST002 has TBKT = 4.33 (Eligible = NO) in Programming. | H8: TCK=6.0 | I8: 1. Open Programming grade list; 2. Locate final exam grade (TCK) cell for ST002; 3. Try clicking or typing '6.0' in the TCK cell; 4. Observe the UI | J8: The TCK cell for ST002 is disabled (read-only). Hovering displays 'Not eligible for final exam'. Any backend save attempt returns validation error. | L8: Not Run | N8: High | O8: Related Requirement: M03-F03, Business Rules 7.4
A9: TC-M03-008 | B9: Module 03 | C9: M03-F03 | D9: Automatic TBKT Calculation | E9: Allow Final Exam Grade Entry When Eligible (TBKT >= 5.0) | F9: Verify that final exam grade input is enabled and saved successfully for students with status Eligible = YES. | G9: Student ST001 has TBKT = 7.67 (Eligible = YES) in Programming. | H9: TCK=8.5 | I9: 1. Open Programming grade list; 2. Locate final exam grade (TCK) cell for ST001; 3. Click the cell and enter '8.5'; 4. Click Save | J9: Grade input behaves normally. Final exam grade '8.5' is saved successfully in database and displayed in UI. | L9: Not Run | N9: High | O9: Related Requirement: M03-F03, Business Rules 7.4
A10: TC-M03-009 | B10: Module 03 | C10: M03-F03 | D10: Automatic TBKT Calculation | E10: Input Retake Exam Grade for Student | F10: Verify that staff can enter a retake exam grade (TLCK) manually and optionally for a student. | G10: Student ST001 has a final exam grade (TCK) recorded. | H10: TLCK=7.0 | I10: 1. Open Programming grade list; 2. Click the retake exam grade (TLCK) cell for ST001; 3. Enter '7.0' and click Save | J10: Retake grade is recorded successfully and displayed in student's grade row. Other grades remain intact. | L10: Not Run | N10: High | O10: Related Requirement: M03-F03, Business Rules 7.2
A11: TC-M03-010 | B11: Module 03 | C11: M03-F04 | D11: Grade Upload via CSV | E11: Bulk Grade Upload via CSV (Overwrite Mode) | F11: Verify that CSV grade import overwrites all existing grades of students in the subject with the new values. | G11: Subject English has existing grades for ST001 (KT_TX=5.0) and ST002 (KT_TX=6.0). | H11: CSV containing: StudentID, KT_TX, DK1. Rows: 'ST001,8.0,9.0' and 'ST002,7.5,8.0' | I11: 1. Select subject 'English'; 2. Click Upload Grades via CSV; 3. Select new CSV file and confirm upload; 4. Observe grade list | J11: Upload succeeds. Grades for ST001 update to KT_TX=8.0, DK1=9.0 (TBKT=8.67), and ST002 update to KT_TX=7.5, DK1=8.0 (TBKT=7.83). Old grades are overwritten. | L11: Not Run | N11: High | O11: Related Requirement: M03-F04, Business Rules 7.5
A12: TC-M03-011 | B12: Module 03 | C12: M03-F04 | D12: Grade Upload via CSV | E12: CSV Grade Upload with Blank Cells Clears Existing Grades | F12: Verify that blank cells in CSV file are interpreted as NULL/Empty and clear corresponding old grades. | G12: Student ST001 has grades (KT_TX=8.0, DK1=9.0). | H12: CSV row: ST001,,9.0 (empty KT_TX value between commas) | I12: 1. Select subject, click Upload Grades via CSV; 2. Select CSV containing empty KT_TX for ST001; 3. Confirm import | J12: Grade list is updated. Regular test grade (KT_TX) for ST001 (previously 8.0) is cleared/empty. DK1 remains 9.0. | L12: Not Run | N12: High | O12: Related Requirement: M03-F04, CSV Import Rules 8
A13: TC-M03-012 | B13: Module 03 | C13: M03-F04 | D13: Grade Upload via CSV | E13: CSV Grade Upload Fails due to Missing StudentID Column | F13: Verify that CSV grade import rejects files missing the StudentID column and does not modify any data. | G13: Staff user is logged in. | H13: CSV with KT_TX, DK1, TCK columns (no StudentID column) | I13: 1. Select subject, click Upload Grades via CSV; 2. Select CSV missing StudentID column and upload; 3. Observe error message | J13: System rejects the CSV file and displays error: 'Missing required column StudentID'. No grades are modified. | L13: Not Run | N13: High | O13: Related Requirement: M03-F04, Error Handling 10
A14: TC-M03-013 | B14: Module 03 | C14: M03-F04 | D14: Grade Upload via CSV | E14: CSV Grade Upload Fails due to Decimal Comma Format (8,5) | F14: Verify that decimal grades formatted with commas (e.g. 8,5) instead of dots (8.5) trigger error. | G14: Staff user is logged in. | H14: CSV row: ST001,8,5,9.0 (or double quoted ST001,\8 | I14: 5\" | J14: 9.0)" | L14: Not Run | N14: 1. Click Upload Grades via CSV; 2. Select CSV containing '8,5' for ST001; 3. Observe response | O14: System blocks import or warns of invalid decimal format requiring dot '.'. Grade is not saved incorrectly.
A15: TC-M03-014 | B15: Module 03 | C15: M03-F04 | D15: Grade Upload via CSV | E15: CSV Grade Upload Fails due to Out of Range Grades (0-10) | F15: Verify that grades outside the 0-10 scale in CSV are rejected. | G15: Staff user is logged in. | H15: CSV row: ST001,11.0,8.0 (KT_TX = 11.0) | I15: 1. Click Upload Grades via CSV; 2. Select CSV with invalid grade '11.0'; 3. Observe error message | J15: System blocks import and displays validation error: 'Grade must be between 0 and 10.' at the corresponding row. No grades are saved. | L15: Not Run | N15: High | O15: Related Requirement: M03-F04, Validation Rules 9
A16: TC-M03-015 | B16: Module 03 | C16: M03-F07 | D16: Manual GPA & Letter Grade Entry | E16: Manually Upload Semester GPA and Letter Grade via CSV | F16: Verify that final score, GPA, and letter grades can be manually imported from CSV and preserved without automatic recalculation. | G16: Student ST001 has semester grade record. | H16: CSV with StudentID, FinalScore, GPA, LetterGrade. Row: ST001,8.5,3.6,A | I16: 1. Navigate to GPA & Letter Grade CSV import; 2. Select CSV containing GPA=3.6 and LetterGrade=A for ST001; 3. View ST001 semester transcript details | J16: GPA=3.6 and LetterGrade=A are saved and displayed exactly. No auto-recalculations are performed on these fields. | L16: Not Run | N16: High | O16: Related Requirement: M03-F07, Business Rules 7.7
... A23: TC-M03-022 | B23: Module 03 | C23: M03-F03 | D23: Automatic TBKT Calculation | E23: TBKT Calculation Independence with Varying Periodic Test Counts (n) | F23: Verify that TBKT formula calculates correctly for subjects with different numbers of periodic tests (n from 1 to 6). | G23: Subject A has 1 periodic test (DK1); Subject B has 3 periodic tests (DK1, DK2, DK3). | H23: Subject A: KT_TX=6.0; DK1=7.0. Subject B: KT_TX=6.0; DK1=7.0; DK2=8.0; DK3=9.0. | I23: 1. Under Subject A, enter KT_TX=6.0 and DK1=7.0 for ST001, save; 2. Under Subject B, enter KT_TX=6.0, DK1=7.0, DK2=8.0, DK3=9.0 for ST001, save; 3. Compare TBKT scores for ST001 | J23: Subject A TBKT is 6.67 (formula: (6.0*1 + 7.0*2)/3 = 6.67). Subject B TBKT is 7.71 (formula: (6.0*1 + 7.0*2 + 8.0*2 + 9.0*2)/7 = 7.71). Both are calculated independently and correctly. | L23: Not Run | N23: High | O23: Related Requirement: TBKT Calculation Formula

Sheet Module 04
A1: ID | B1: Module | C1: Feature ID | D1: Feature Name | E1: Title | F1: Objective | G1: Preconditions | H1: TestData | I1: Steps | J1: ExpectedResult | K1: Actual Result | L1: Status | M1: Evidence | N1: Priority | O1: Notes
A2: TC-M04-001 | B2: Module 04 | C2: M04-F01 | D2: Council Feedback Record | E2: Record Council Feedback Successful | F2: Verify that staff can successfully record a Class Council record with comments from all departments. | G2: Staff user is logged in. Student ST001 and Semester 1 exist. No council record exists for ST001 in Semester 1. | H2: Student=ST001; Semester=Semester 1; GeneralComment=Strong learning attitude; ITComment=Excellent coding skills; EnglishComment=Fluent communicator; PLTComment=Highly cooperative; EducatorComment=Good behavior | I2: 1. Navigate to Class Council Management; 2. Click Create Council Record; 3. Select Student ST001 and Semester 'Semester 1'; 4. Enter General Comment 'Strong learning attitude'; 5. Enter IT Comment 'Excellent coding skills'; 6. Enter English Comment 'Fluent communicator'; 7. Enter PLT Comment 'Highly cooperative'; 8. Enter Educator Comment 'Good behavior'; 9. Click Save | J2: The record is saved successfully. A success message appears. The student's record is displayed in the list with all comments. | K2: The record is saved successfully. A success message appears. The student's record is displayed in the list with all comments. | L2: Passed | N2: High | O2: Related Requirement: M04-F01
A3: TC-M04-002 | B3: Module 04 | C3: M04-F01 | D3: Council Feedback Record | E3: Record Council Feedback with Empty Optional Fields | F3: Verify that saving a completely empty council feedback record is allowed without validation errors. | G3: Staff user is logged in. Student ST002 and Semester 1 exist. No record exists for ST002 in Semester 1. | H3: Student=ST002; Semester=Semester 1; AllComments=Empty; Warning=False; WarningReason=Empty | I3: 1. Navigate to Class Council Management; 2. Click Create Council Record; 3. Select Student ST002 and Semester 'Semester 1'; 4. Leave all comment fields empty; 5. Ensure Warning is unchecked and Warning Reason is blank; 6. Click Save | J3: The record is saved successfully. No validation errors occur. No badges appear on the list for student ST002. | K3: The record is saved successfully. No validation errors occur. No badges appear on the list for student ST002. | L3: Passed | N3: High | O3: Related Requirement: M04-F01, Optional Fields 6.2
A4: TC-M04-003 | B4: Module 04 | C4: M04-F02 | D4: Academic Warning Flag | E4: Set Academic Warning Flag and Warning Reason | F4: Verify that staff can set an academic warning flag and input a warning reason. | G4: Staff user is logged in. Student ST001 and Semester 1 exist. | H4: Student=ST001; Semester=Semester 1; Warning=True; WarningReason=Attendance below required level | I4: 1. Open the council record for ST001 in Semester 1; 2. Check the 'Academic Warning' checkbox; 3. Enter Warning Reason: 'Attendance below required level'; 4. Click Save | J4: The record is saved successfully. The warning badge (⚠) appears next to the student's name in the list. | K4: The record is saved successfully. The warning badge (⚠) appears next to the student's name in the list. | L4: Passed | N4: High | O4: Related Requirement: M04-F02, Academic Warning 6.3
A5: TC-M04-004 | B5: Module 04 | C5: M04-F02 | D5: Academic Warning Flag | E5: Set Academic Warning Flag with Empty Warning Reason | F5: Verify that warning reason is optional and saving warning flag without a reason is allowed. | G5: Staff user is logged in. | H5: Student=ST001; Semester=Semester 1; Warning=True; WarningReason=Empty | I5: 1. Open the council record for ST001 in Semester 1; 2. Check the 'Academic Warning' checkbox; 3. Leave 'Warning Reason' empty; 4. Click Save | J5: The record is saved successfully. No validation errors occur. The warning badge (⚠) is displayed on the student list. | K5: The record is saved successfully. No validation errors occur. The warning badge (⚠) is displayed on the student list. | L5: Passed | N5: High | O5: Related Requirement: M04-F02, Optional Fields 6.2, Validation Rules 7
A6: TC-M04-005 | B6: Module 04 | C6: M04-F04 | D6: Auto Draft Saving | E6: Verify Automatic Draft Saving in Browser Local Storage | F6: Verify that the system automatically saves typed comments into local storage in the background. | G6: Staff user is logged in. Bi-directional sync/save has not been initiated. | H6: Student=ST003; Semester=Semester 1; ITComment=Draft comment for IT department | I6: 1. Open the council record for ST003 in Semester 1; 2. Type IT Comment 'Draft comment for IT department'; 3. Do NOT click Save; 4. Open Developer Tools -> Application -> Local Storage | J6: The text 'Draft comment for IT department' is saved automatically to browser Local Storage under a key representing ST003/Semester 1 as typing occurs. | K6: The text 'Draft comment for IT department' is saved automatically to browser Local Storage under a key representing ST003/Semester 1 as typing occurs. | L6: Passed | N6: High | O6: Related Requirement: M04-F04, Automatic Draft Saving 6.5
A7: TC-M04-006 | B7: Module 04 | C7: M04-F05 | D7: Draft Recovery / Discard | E7: Recover Unsaved Draft after Unexpected Browser Closure | F7: Verify that the system detects unsaved local drafts and displays a prompt to restore them. | G7: Unsaved draft for ST003 with ITComment='Draft comment for IT department' exists in Local Storage. Sheets database does not have this comment. | H7: Student=ST003; Semester=Semester 1 | I7: 1. Close browser and reopen it (simulating crash); 2. Navigate back to the council record for ST003 in Semester 1; 3. Verify prompt; 4. Select 'Continue editing' | J7: An 'Unsaved Draft' warning/prompt is shown. Selecting 'Continue editing' restores the draft text 'Draft comment for IT department' to the IT Comment text box. | K7: An 'Unsaved Draft' warning/prompt is shown. Selecting 'Continue editing' restores the draft text 'Draft comment for IT department' to the IT Comment text box. | L7: Passed | N7: High | O7: Related Requirement: M04-F05, Draft Recovery 6.6
A8: TC-M04-007 | B8: Module 04 | C8: M04-F05 | D8: Draft Recovery / Discard | E8: Discard Unsaved Draft to Restore Last Saved Data | F8: Verify that choosing to discard an unsaved draft removes it and restores the last saved data from database. | G8: Official database record for ST003 has ITComment='Good student'. Unsaved draft in Local Storage has ITComment='Draft edit'. | H8: Student=ST003; Semester=Semester 1 | I8: 1. Open council record for ST003 in Semester 1; 2. When 'Unsaved Draft' prompt appears, select 'Discard draft'; 3. Check the IT Comment text box | J8: Local Storage draft is cleared. The IT Comment reverts to the database value 'Good student'. Draft edits are discarded. | K8: Local Storage draft is cleared. The IT Comment reverts to the database value 'Good student'. Draft edits are discarded. | L8: Passed | N8: High | O8: Related Requirement: M04-F05, Draft Recovery 6.6
A9: TC-M04-008 | B9: Module 04 | C9: M04-F06 | D9: Batch Feedback Entry | E9: Batch Feedback Entry by Comment Type | F9: Verify that staff can enter the same feedback type for multiple students simultaneously in batch mode. | G9: Staff user is logged in. Students ST001, ST002, and ST003 exist in Batch PNV26A. | H9: Batch=PNV26A; Semester=Semester 1; FeedbackType=IT Comment; Comments='Active performance in programming project' for ST001, ST002, and ST003 | I9: 1. Open Batch Feedback page; 2. Select Batch PNV26A, Semester 'Semester 1', and Feedback Type 'IT Comment'; 3. In the grid, type 'Active performance in programming project' for ST001, ST002, and ST003; 4. Click Save All | J9: All three records are saved successfully. Success message 'Saved 3 students' is shown. Selected students have the new IT comment. | K9: All three records are saved successfully. Success message 'Saved 3 students' is shown. Selected students have the new IT comment. | L9: Passed | N9: High | O9: Related Requirement: M04-F06, Batch Feedback 6.7
A10: TC-M04-009 | B10: Module 04 | C10: M04-F06 | D10: Batch Feedback Entry | E10: Batch Feedback Entry Does Not Overwrite Other Comment Fields | F10: Verify that entering batch feedback for one field does not erase other existing comment fields for that student. | G10: Student ST001 has existing ITComment='Excellent coding' and EnglishComment='Good speaking'. | H10: FeedbackType=English Comment; NewEnglishComment='Excellent communication' | I10: 1. Open Batch Feedback page; 2. Select Feedback Type 'English Comment'; 3. Input 'Excellent communication' for ST001 and click Save; 4. Navigate to ST001's council record details | J10: English Comment is updated to 'Excellent communication'. The existing IT Comment is preserved as 'Excellent coding' (not cleared). | K10: English Comment is updated to 'Excellent communication'. The existing IT Comment is preserved as 'Excellent coding' (not cleared). | L10: Passed | N10: High | O10: Related Requirement: M04-F06, Batch Feedback 6.7
A11: TC-M04-010 | B11: Module 04 | C11: M04-F07 | D11: Concurrent Edit Conflict Handling | E11: Three-Way Merge for Non-conflicting Concurrent Edits | F11: Verify that concurrent edits on different fields of the same record are merged successfully using 3-way merge. | G11: Teacher A and Teacher B are logged in. The database record for ST001 has GeneralComment='Good student', other fields are empty. | H11: ST001 record in Semester 1; Teacher B saves ITComment='Excellent'; Teacher A saves EnglishComment='Fluent' | I11: 1. Teacher A opens ST001 council edit form; 2. Teacher B opens ST001 council edit form; 3. Teacher B updates IT Comment to 'Excellent' and clicks Save first; 4. Teacher A updates English Comment to 'Fluent' (IT Comment remains empty on their screen) and clicks Save | J11: Save succeeds. The final record on Sheets is merged: GeneralComment='Good student', ITComment='Excellent', and EnglishComment='Fluent'. Teacher A receives notification of updates by another teacher. | K11: Save succeeds. The final record on Sheets is merged: GeneralComment='Good student', ITComment='Excellent', and EnglishComment='Fluent'. Teacher A receives notification of updates by another teacher. | L11: Passed | N11: High | O11: Related Requirement: M04-F07, Concurrent Editing 6.8
A12: TC-M04-011 | B12: Module 04 | C12: M04-F07 | D12: Concurrent Edit Conflict Handling | E12: Flag Conflict on Concurrent Edits of Same Field | F12: Verify that concurrent edits on the same field block the second user from overwriting first user's saved data and flag a conflict. | G12: Teacher A and Teacher B are logged in. ST001 has ITComment='Good'. | H12: ST001 record in Semester 1; Teacher B saves ITComment='Excellent'; Teacher A saves ITComment='Very Good' | I12: 1. Teacher A opens ST001 edit form; 2. Teacher B opens ST001 edit form; 3. Teacher B changes IT Comment to 'Excellent' and clicks Save; 4. Teacher A changes IT Comment to 'Very Good' and clicks Save after Teacher B | J12: Teacher A's save is blocked or triggers a conflict. An error 'Saved, but these fields were updated by another teacher: IT Comment' is shown. Teacher B's value 'Excellent' is preserved in database. | K12: Teacher A's save is blocked or triggers a conflict. An error 'Saved, but these fields were updated by another teacher: IT Comment' is shown. Teacher B's value 'Excellent' is preserved in database. | L12: Passed | N12: High | O12: Related Requirement: M04-F07, Concurrent Editing 6.8
A13: TC-M04-012 | B13: Module 04 | C13: M04-F08 | D13: PDF Report Export | E13: Export Class Council Report to PDF | F13: Verify that staff can generate and download a PDF report containing student info, semester, comments, and warnings. | G13: Student ST001 has a complete council record in Semester 1. | H13: Student=ST001; Semester=Semester 1 | I13: 1. Open ST001's council record details page; 2. Click Export PDF; 3. Open the downloaded PDF file | J13: The PDF report downloads successfully. It contains student details, Semester 1, all teacher comments, and warning details formatted correctly. | K13: The PDF report downloads successfully. It contains student details, Semester 1, all teacher comments, and warning details formatted correctly. | L13: Passed | N13: High | O13: Related Requirement: M04-F08, PDF Export 6.9
... A34: TC-M04-033 | B34: Module 04 | C34: M04-F08 | D34: PDF Report Export | E34: Export PDF Report for Council Record with Partial Comments | F34: Verify that exporting a PDF report works properly even if some optional department comments are left blank. | G34: Staff user is logged in. ST002 has a saved council record with only IT Comment filled (others empty). | H34: Student=ST002; Semester=Semester 1 | I34: 1. Open council record for ST002 in Semester 1; 2. Click Export PDF; 3. Download and inspect PDF report | J34: PDF report exports successfully without errors. Blank comment sections display 'N/A' or remain neatly empty without breaking PDF layout. | K34: PDF report exports successfully without errors. Blank comment sections display 'N/A' or remain neatly empty without breaking PDF layout. | L34: Passed | N34: Medium | O34: Related Requirement: M04-F08, Business Rule 6.2, 6.9

Sheet Module 05
A1: ID | B1: Module | C1: Feature ID | D1: Feature Name | E1: Title | F1: Objective | G1: Preconditions | H1: TestData | I1: Steps | J1: ExpectedResult | K1: Actual Result | L1: Status | M1: Evidence | N1: Priority | O1: Notes
A2: TC-M05-001 | B2: Module 05 - Internship Management | C2: M05-F01 | D2: Internship Group Creation | E2: Create New Internship Group with Valid Information | F2: Verify functionality for creating a new internship group when entering all required and valid information. | G2: User is logged in as Staff. Currently on Internship Management interface. Classes "PNV26A" and "PNV26B" exist in system and are not assigned to any internship group in the same academic year. | H2: GroupName="Internship Group 2026"; AcademicYear="2026"; Classes="PNV26A, PNV26B"; StartDate="2026-06-01" | I2: 1. Click Create New Internship Group button; 2. Enter Group Name as "Internship Group 2026"; 3. Select Academic Year as "2026"; 4. Select classes "PNV26A" and "PNV26B"; 5. Select Start Date as "2026-06-01"; 6. Click Save button. | J2: Internship group is created successfully. Success notification appears and "Internship Group 2026" is displayed in the active internship group list with 2 assigned classes. | K2: Internship group is created successfully. Success notification appears and "Internship Group 2026" is displayed in the active internship group list with 2 assigned classes. | L2: Passed | N2: High | O2: Related Requirement: M05-F01, Rule 6.1
A3: TC-M05-002 | B3: Module 05 - Internship Management | C3: M05-F01 | D3: Internship Group Creation | E3: Internship Group Creation Fails Due to Empty Group Name | F3: Verify system displays error and prevents creating internship group when group name is blank. | G3: User is logged in as Staff. Currently on Create New Internship Group interface. Class "PNV26A" is not assigned to any internship group in the academic year. | H3: GroupName=""; AcademicYear="2026"; Classes="PNV26A"; StartDate="2026-06-01" | I3: 1. Leave Group Name blank; 2. Select Academic Year as "2026"; 3. Select class "PNV26A"; 4. Select Start Date as "2026-06-01"; 5. Click Save button. | J3: System blocks creation. Validation error message appears: "Group Name is required." Form remains open and no new record is created. | K3: System blocks creation. Validation error message appears: "Group Name is required." Form remains open and no new record is created. | L3: Passed | N3: High | O3: Related Requirement: M05-F01, Rule 6.1, Validation Rules (Section 8)
A4: TC-M05-003 | B4: Module 05 - Internship Management | C4: M05-F01 | D4: Internship Group Creation | E4: Internship Group Creation Fails Due to Unselected Classes | F4: Verify system displays error and prevents creating internship group when no classes are selected. | G4: User is logged in as Staff. Currently on Create New Internship Group interface. | H4: GroupName="Internship Group 2026"; AcademicYear="2026"; Classes=None; StartDate="2026-06-01" | I4: 1. Enter Group Name as "Internship Group 2026"; 2. Select Academic Year as "2026"; 3. Do not select any class checkbox; 4. Select Start Date as "2026-06-01"; 5. Click Save button. | J4: System blocks creation. Validation error message appears: "At least one class must be selected." Group is not created. | K4: System blocks creation. Validation error message appears: "At least one class must be selected." Group is not created. | L4: Passed | N4: High | O4: Related Requirement: M05-F01, Rule 6.1, Validation Rules (Section 8)
A5: TC-M05-004 | B5: Module 05 - Internship Management | C5: M05-F01 | D5: Internship Group Creation | E5: Internship Group Creation Fails Due to Missing Start Date | F5: Verify system displays error and prevents creating internship group when Start Date is empty. | G5: User is logged in as Staff. Currently on Create New Internship Group interface. | H5: GroupName="Internship Group 2026"; AcademicYear="2026"; Classes="PNV26A"; StartDate="" | I5: 1. Enter Group Name as "Internship Group 2026"; 2. Select Academic Year as "2026"; 3. Select class "PNV26A"; 4. Leave Start Date blank; 5. Click Save button. | J5: System blocks creation. Validation error message appears: "Start Date is required." Group is not created. | K5: System blocks creation. Validation error message appears: "Start Date is required." Group is not created. | L5: Passed | N5: High | O5: Related Requirement: M05-F01, Rule 6.1, Validation Rules (Section 8)
A6: TC-M05-005 | B6: Module 05 - Internship Management | C6: M05-F01 | D6: Internship Group Creation | E6: Internship Group Creation Fails Due to Missing Academic Year | F6: Verify system displays error and prevents creating internship group when Academic Year is empty. | G6: User is logged in as Staff. Currently on Create New Internship Group interface. | H6: GroupName="Internship Group 2026"; AcademicYear=""; Classes="PNV26A"; StartDate="2026-06-01" | I6: 1. Enter Group Name as "Internship Group 2026"; 2. Leave Academic Year dropdown unselected/empty; 3. Select class "PNV26A"; 4. Select Start Date as "2026-06-01"; 5. Click Save button. | J6: System blocks creation. Validation error message appears: "Academic Year is required." Group is not created. | K6: System blocks creation. Validation error message appears: "Academic Year is required." Group is not created. | L6: Passed | N6: High | O6: Related Requirement: M05-F01, Rule 6.1, Validation Rules (Section 8)
A7: TC-M05-006 | B7: Module 05 - Internship Management | C7: M05-F01 | D7: Internship Group Creation | E7: Create Internship Group Successfully When Assigning Same Class across Different Academic Years | F7: Verify system allows assigning the same class to another internship group if the academic years are different. | G7: User is logged in as Staff. Class "PNV26A" was assigned to an internship group in academic year 2025. | H7: GroupName="Internship Group 2026"; AcademicYear="2026"; Classes="PNV26A"; StartDate="2026-06-01" | I7: 1. Create new group with Academic Year "2026"; 2. Select class "PNV26A"; 3. Click Save button. | J7: System allows creation successfully without duplicate class error because academic years differ (2025 vs 2026). | K7: System allows creation successfully without duplicate class error because academic years differ (2025 vs 2026). | L7: Passed | N7: Medium | O7: Related Requirement: M05-F01, Rule 6.1
A8: TC-M05-007 | B8: Module 05 - Internship Management | C8: M05-F03 | D8: Partner Company Management | E8: Add New Partner Company with Valid Name | F8: Verify functionality for adding a new partner company with a valid name. | G8: User is logged in as Staff. Currently on Company Management interface. Company "ABC Technology" does not exist in system. | H8: CompanyName="ABC Technology" | I8: 1. Click Add Company button; 2. Enter Company Name as "ABC Technology"; 3. Click Save button. | J8: Company is added successfully. Success notification appears and "ABC Technology" is displayed in company list with status Active. | K8: Company is added successfully. Success notification appears and "ABC Technology" is displayed in company list with status Active. | L8: Passed | N8: High | O8: Related Requirement: M05-F03, Rule 6.3
A9: TC-M05-008 | B9: Module 05 - Internship Management | C9: M05-F03 | D9: Partner Company Management | E9: Add Company Fails Due to Empty Company Name | F9: Verify system displays error and prevents adding company when company name is empty. | G9: User is logged in as Staff. Currently on Add Company dialog. | H9: CompanyName="" | I9: 1. Leave Company Name field empty; 2. Click Save button. | J9: System blocks action. Validation error message appears: "Company Name is required." No new company is saved. | K9: System blocks action. Validation error message appears: "Company Name is required." No new company is saved. | L9: Passed | N9: High | O9: Related Requirement: M05-F03, Rule 6.3, Validation Rules (Section 8)
A10: TC-M05-009 | B10: Module 05 - Internship Management | C10: M05-F03 | D10: Partner Company Management | E10: Add Company Fails Due to Duplicate Name (Case Insensitive) | F10: Verify system detects duplicate company names regardless of uppercase/lowercase letters. | G10: User is logged in as Staff. Company "ABC Technology" already exists in system. | H10: CompanyName="abc technology" | I10: 1. Click Add Company button; 2. Enter Company Name as "abc technology"; 3. Click Save button. | J10: System blocks action. Error message appears: "Company name already exists." Duplicate company is not created. | K10: System blocks action. Error message appears: "Company name already exists." Duplicate company is not created. | L10: Passed | N10: High | O10: Related Requirement: M05-F03, Rule 6.3
